<?xml version="1.0" encoding="UTF-8"?>
<!-- Generated by org.testng.reporters.JUnitXMLReporter -->
<testsuite hostname="MS-20160617BOYN" name="搜索诺基亚、投诉" tests="2" failures="1" timestamp="4 Feb 2018 15:52:24 GMT" time="16.23" errors="0">
  <testcase name="case1" time="13.344" classname="cases.Case1">
    <failure type="java.lang.AssertionError" message="expected [0] but found [1]">
      <![CDATA[java.lang.AssertionError: expected [0] but found [1]
	at base.CheckPoint.result(CheckPoint.java:26)
	at cases.Case1.case1(Case1.java:40)
	at java.util.concurrent.FutureTask.run(Unknown Source)
	at java.util.concurrent.ThreadPoolExecutor.runWorker(Unknown Source)
	at java.util.concurrent.ThreadPoolExecutor$Worker.run(Unknown Source)
	at java.lang.Thread.run(Unknown Source)
... Removed 21 stack frames]]>
    </failure>
  </testcase> <!-- case1 -->
  <testcase name="case02" time="2.819" classname="cases.Case2"/>
</testsuite> <!-- 搜索诺基亚、投诉 -->
